Workbook

Sheet README
B2: LOAD SELECTION & PROFITABILITY DECISION MODEL — v3
B3: Owner-operator freight evaluation | Christopher D. Sheppard | 18 completed trips, settlement-derived cost stack Built on eighteen completed loads from my own operation. Cost-per-mile inputs are derived from my own settlement history, using multi-year averages for the fixed and variable components and the most recent three weeks as current-period figures. These are actual operating numbers from a single owner-operator. They are not third-party audited results and, except for the explicitly labeled tire reserve, they are not industry benchmarks.
B5: VERSION HISTORY
B6: v1 — Seven representative lanes, illustrative cost figures. Nothing in it could be shown wrong because nothing had been tested.
B7: v2 — Rebuilt on 18 completed trips with operator scores. Removed a $0.280/mi truck payment on equipment owned outright, made fuel
B8: economy depend on weight class, and re-weighted destination value from 15% to 25% after correlation testing.
B9: v3 — Cost stack source-checked line by line against my own settlement history: multi-year averages plus the most recent three weeks as current-period figures.
B10: Assumptions tab traces fixed and variable components to settlement-derived figures. The tire reserve is explicitly labeled as the one industry placeholder.
B12: WHAT THE STATEMENT CONFIRMED
B13: The 18-load sample blends to $2.1599 per mile. The statement year to date reads $2.163. That is a 0.15% difference across 19,214 sample
B14: miles against 56,752 year-to-date miles, which means the sample is a fair slice of the year and not a flattering selection.
B16: One trip in the sample (L-18) appears on this settlement, so a single load can be reconciled end to end. Loaded miles matched exactly and the
... B61: the figures reproduced here are per-mile aggregates and one trip reconciliation only.

Sheet Assumptions
B2: OPERATING ASSUMPTIONS
B3: v3 — cost-per-mile inputs below are derived from my own settlement history: multi-year averages for fixed and variable components, with the most recent three weeks used as current-period figures. The tire reserve is explicitly labeled as the one industry placeholder.
B5: FUEL
B6: Diesel pump price ($/gal) | C6: 4.933 | D6: Settlement wk 26/07/31: 120.3 gal for $593.44. Update to what you are paying.
B7: Prime fuel discount ($/gal) | C7: 0.857 | D7: Derived: YTD discount $0.119/mi at 7.20 blended mpg. Statement line TRACTOR FUEL DISCOUNT.
B8: Net diesel ($/gal) | C8: =C6-C7 -> 4.076 | D8: What fuel actually costs you after the discount. This is the figure the model burns.
B9: MPG — heavy (60,000 lb +) | C9: 7 | D9: Operator-reported 6.5 to 7.7. YTD blended across all weight classes computes to 7.20.
B10: MPG — medium (25,000-60,000 lb) | C10: 8.5 | D10: Estimated. L-17 at roughly 24,000 lb is the nearest observed point.
B11: MPG — light (under 25,000 lb) | C11: 10 | D11: Operator-reported 9 to 11 on L-08, L-11, L-15, L-16.
B13: OTHER VARIABLE COST PER MILE (from the operating statement, YTD actual)
B14: DEF, net of discount | C14: 0.023 | D14: Statement: TRACTOR DEF $0.031 less DEF DISCOUNT $0.008.
B15: State fuel tax | C15: 0.007 | D15: Statement: STATE FUEL TAX, YTD.
B16: Maintenance & repair | C16: 0.12 | D16: YTD $0.065, lifetime $0.070 — but both come from one truck the operator deliberately went easy on while purchasing it. Set at $0.120. See Settlement Recon.
B17: Tires (NOT a statement figure) | C17: 0.045 | D17: The statement nets to zero because Prime runs no tire fund for owner-operators — those lines are vestigial. Tires are paid personally and appear nowhere. Explicit industry placeholder; replace with actual spend.
B18: Tolls, Qualcomm, washing, misc | C18: 0.045 | D18: Statement MISCELLANEOUS less advances and emergency-fund transfers, which are not operating costs.
B19: TOTAL NON-FUEL VARIABLE CPM | C19: =SUM(C14:C18) -> 0.24 | D19: Fuel is excluded here because it is priced per load from the weight class.
B21: FIXED COST
B22: Working weeks per year | C22: 44 | D22: 52 less roughly 8 weeks of home time. A typical year, not the lifetime average.
B23: Miles per working week | C23: 2600 | D23: Operator-reported 2,500 to 3,000. Set toward the low end because partial weeks count as working weeks.
B24: Annual miles driven | C24: =C22*C23 -> 114400 | D24: Derived, not lifted from the statement. See the note below on why the lifetime average is the wrong number here.
B25: Truck payment (annual) | C25: 0 | D25: Lease purchase completed January 2025. Statement RENT PAYMENT shows $0 current, $0.437/mi lifetime.
B26: Physical damage insurance (annual) | C26: 6163 | D26: YTD $0.061/mi annualised. Statement PHYSICAL DAMAGE INSURANCE.
B27: License and permits (annual) | C27: 2830 | D27: YTD $0.028/mi annualised. Statement LICENSE AND PERMITS.
B28: Operator occupational accident (annual) | C28: 1617 | D28: YTD $0.016/mi annualised. Statement OPERATOR OCCUP ACC.
B29: Statement prep, BT/DH, federal highway tax (annual) | C29: 2123 | D29: YTD $0.008 + $0.003 + $0.010 per mile annualised.
B30: TOTAL FIXED CPM | C30: =(C25+C26+C27+C28+C29)/C24 -> 0.11130245 | D30: Spread across total miles, loaded and empty. Statement TOTAL FIXED COST reads $0.128 YTD.
B32: BREAK-EVEN — THE NUMBER A LOAD MUST BEAT
B33: All-in CPM — heavy load | C33: =C8/C9+C19+C30 -> 0.93358816 | D33: Applied to total miles. Deadhead burns fuel and hours while earning nothing.
B34: All-in CPM — medium load | C34: =C8/C10+C19+C30 -> 0.83083186
B35: All-in CPM — light load | C35: =C8/C11+C19+C30 -> 0.75890245
B37: Cost advantage vs. financed operator | C37: =33600/C24 -> 0.29370629 | D37: A comparable owner-operator carrying a $33,600 annual note breaks even this much higher per mile.
B38: Advantage across the 18-load sample | C38: ='Load Board'!J23*C37 -> 5643.2727 | D38: Dollars of structural cost advantage across 19,214 miles.
B39: Advantage across YTD miles | C39: =C37*56752 -> 16668.42 | D39: Statement year-to-date miles are 56,752. This is the head start over a driver still paying for the truck.
B41: SENSITIVITY — annual miles is the assumption break-even is most exposed to
B42: Annual miles | C42: Fixed CPM | D42: Resulting heavy break-even, and what the mileage figure represents
B43: 98000 | C43: =($C$25+$C$26+$C$27+$C$28+$C$29)/B43 -> 0.12992857 | D43: =TEXT($C$8/$C$9+$C$19+C43,"$0.000")&" — a year like the one after the baby was born" -> $0.952 — a year like the one after the baby was born
B44: 101057 | C44: =($C$25+$C$26+$C$27+$C$28+$C$29)/B44 -> 0.1259982 | D44: =TEXT($C$8/$C$9+$C$19+C44,"$0.000")&" — the raw lifetime average — includes that year, so it understates a normal one" -> $0.948 — the raw lifetime average — includes that year, so it understates a normal one
B45: 114400 | C45: =($C$25+$C$26+$C$27+$C$28+$C$29)/B45 -> 0.11130245 | D45: =TEXT($C$8/$C$9+$C$19+C45,"$0.000")&" — MODEL DEFAULT — 44 working weeks at 2,600 miles" -> $0.934 — MODEL DEFAULT — 44 working weeks at 2,600 miles
B46: 132000 | C46: =($C$25+$C$26+$C$27+$C$28+$C$29)/B46 -> 0.096462121 | D46: =TEXT($C$8/$C$9+$C$19+C46,"$0.000")&" — 44 weeks at 3,000, the top of the operator-reported range" -> $0.919 — 44 weeks at 3,000, the top of the operator-reported range
B48: DECISION THRESHOLDS
...

Sheet Load Board
B1: LOAD BOARD — 18 completed trips, Prime Inc. flatbed
B2: Revenue and mileage from Prime app trip history. See Settlement Recon: on the one load that can be checked, the app overstated total miles by 5.3%, so rate per mile here is conservative.
B3: Load | C3: Origin | D3: Destination | E3: Commodity | F3: Weight Class | G3: Revenue | H3: Loaded Mi | I3: Empty Mi | J3: Total Mi | K3: Drive Hrs | L3: Dwell Hrs | M3: Total Hrs | N3: Gross $/Mi | O3: Est MPG | P3: Fuel Cost | Q3: Other Var | R3: Fixed Cost | S3: Total Cost | T3: Net Contrib | U3: Net $/Mi | V3: Net $/Hr | W3: DH % | X3: Rate | Y3: Dest | Z3: Time | AA3: DH | AB3: Dwell | AC3: Secure | AD3: Route | AE3: HOS | AF3: Weighted | AG3: Gate | AH3: DECISION | AI3: Op Score | AJ3: Var
B4: L-01 | C4: Visalia, CA | D4: Peoria, AZ | E4: Metal building components | F4: Medium | G4: 1599.11 | H4: 558 | I4: 212 | J4: =H4+I4 -> 770 | K4: =J4/Assumptions!$C$53 -> 14.807692 | L4: 2 | M4: =K4+L4 -> 16.807692 | N4: =IFERROR(G4/J4,0) -> 2.0767662 | O4: =IF(F4="Heavy",Assumptions!$C$9,IF(F4="Medium",Assumptions!$C$10,Assumptions!$C$11)) -> 8.5 | P4: =J4/O4*Assumptions!$C$8 -> 369.23765 | Q4: =J4*Assumptions!$C$19 -> 184.8 | R4: =J4*Assumptions!$C$30 -> 85.702885 | S4: =P4+Q4+R4 -> 639.74053 | T4: =G4-S4 -> 959.36947 | U4: =IFERROR(T4/J4,0) -> 1.2459344 | V4: =IFERROR(T4/M4,0) -> 57.07919 | W4: =IFERROR(I4/J4,0) -> 0.27532468 | X4: =IF(U4>=RATE5,5,IF(U4>=RATE4,4,IF(U4>=RATE3,3,IF(U4>=RATE2,2,1)))) -> 3 | Y4: 4 | Z4: =IF(V4>=TIME5,5,IF(V4>=TIME4,4,IF(V4>=TIME3,3,IF(V4>=TIME2,2,1)))) -> 3 | AA4: =IF(W4<=0.05,5,IF(W4<=0.1,4,IF(W4<=0.18,3,IF(W4<=0.28,2,1)))) -> 2 | AB4: 4 | AC4: 5 | AD4: 4 | AE4: 5 | AF4: =X4*WRATE+Y4*WDEST+Z4*WTIME+AA4*WDH+AB4*WDWELL+AC4*WSEC+AD4*WROUTE+AE4*WHOS -> 3.5 | AG4: =IF(OR(T4<0,W4>Assumptions!$C$49,AE4<=1),"FAIL","PASS") -> PASS | AH4: =IF(AG4="FAIL","DECLINE - gate",IF(AF4>=Assumptions!$C$50,"ACCEPT",IF(AF4>=Assumptions!$C$51,"NEGOTIATE","DECLINE - score"))) -> NEGOTIATE | AI4: 8 | AJ4: =AF4*2-AI4 -> -1
B5: L-02 | C5: Tempe, AZ | D5: Rayville, LA | E5: AC units | F5: Light | G5: 2870.62 | H5: 1312 | I5: 24 | J5: =H5+I5 -> 1336 | K5: =J5/Assumptions!$C$53 -> 25.692308 | L5: 1 | M5: =K5+L5 -> 26.692308 | N5: =IFERROR(G5/J5,0) -> 2.1486677 | O5: =IF(F5="Heavy",Assumptions!$C$9,IF(F5="Medium",Assumptions!$C$10,Assumptions!$C$11)) -> 10 | P5: =J5/O5*Assumptions!$C$8 -> 544.5536 | Q5: =J5*Assumptions!$C$19 -> 320.64 | R5: =J5*Assumptions!$C$30 -> 148.70007 | S5: =P5+Q5+R5 -> 1013.8937 | T5: =G5-S5 -> 1856.7263 | U5: =IFERROR(T5/J5,0) -> 1.3897652 | V5: =IFERROR(T5/M5,0) -> 69.560352 | W5: =IFERROR(I5/J5,0) -> 0.017964072 | X5: =IF(U5>=RATE5,5,IF(U5>=RATE4,4,IF(U5>=RATE3,3,IF(U5>=RATE2,2,1)))) -> 3 | Y5: 4 | Z5: =IF(V5>=TIME5,5,IF(V5>=TIME4,4,IF(V5>=TIME3,3,IF(V5>=TIME2,2,1)))) -> 4 | AA5: =IF(W5<=0.05,5,IF(W5<=0.1,4,IF(W5<=0.18,3,IF(W5<=0.28,2,1)))) -> 5 | AB5: 5 | AC5: 5 | AD5: 4 | AE5: 5 | AF5: =X5*WRATE+Y5*WDEST+Z5*WTIME+AA5*WDH+AB5*WDWELL+AC5*WSEC+AD5*WROUTE+AE5*WHOS -> 4.05 | AG5: =IF(OR(T5<0,W5>Assumptions!$C$49,AE5<=1),"FAIL","PASS") -> PASS | AH5: =IF(AG5="FAIL","DECLINE - gate",IF(AF5>=Assumptions!$C$50,"ACCEPT",IF(AF5>=Assumptions!$C$51,"NEGOTIATE","DECLINE - score"))) -> ACCEPT | AI5: 9 | AJ5: =AF5*2-AI5 -> -0.9
B6: L-03 | C6: Natchitoches, LA | D6: Salt Lake City, UT | E6: Lumber, untarped | F6: Heavy | G6: 3833.03 | H6: 1489 | I6: 132 | J6: =H6+I6 -> 1621 | K6: =J6/Assumptions!$C$53 -> 31.173077 | L6: 1 | M6: =K6+L6 -> 32.173077 | N6: =IFERROR(G6/J6,0) -> 2.3646083 | O6: =IF(F6="Heavy",Assumptions!$C$9,IF(F6="Medium",Assumptions!$C$10,Assumptions!$C$11)) -> 7 | P6: =J6/O6*Assumptions!$C$8 -> 943.88514 | Q6: =J6*Assumptions!$C$19 -> 389.04 | R6: =J6*Assumptions!$C$30 -> 180.42127 | S6: =P6+Q6+R6 -> 1513.3464 | T6: =G6-S6 -> 2319.6836 | U6: =IFERROR(T6/J6,0) -> 1.4310201 | V6: =IFERROR(T6/M6,0) -> 72.100147 | W6: =IFERROR(I6/J6,0) -> 0.081431215 | X6: =IF(U6>=RATE5,5,IF(U6>=RATE4,4,IF(U6>=RATE3,3,IF(U6>=RATE2,2,1)))) -> 4 | Y6: 5 | Z6: =IF(V6>=TIME5,5,IF(V6>=TIME4,4,IF(V6>=TIME3,3,IF(V6>=TIME2,2,1)))) -> 4 | AA6: =IF(W6<=0.05,5,IF(W6<=0.1,4,IF(W6<=0.18,3,IF(W6<=0.28,2,1)))) -> 4 | AB6: 5 | AC6: 5 | AD6: 3 | AE6: 5 | AF6: =X6*WRATE+Y6*WDEST+Z6*WTIME+AA6*WDH+AB6*WDWELL+AC6*WSEC+AD6*WROUTE+AE6*WHOS -> 4.4 | AG6: =IF(OR(T6<0,W6>Assumptions!$C$49,AE6<=1),"FAIL","PASS") -> PASS | AH6: =IF(AG6="FAIL","DECLINE - gate",IF(AF6>=Assumptions!$C$50,"ACCEPT",IF(AF6>=Assumptions!$C$51,"NEGOTIATE","DECLINE - score"))) -> ACCEPT | AI6: 8 | AJ6: =AF6*2-AI6 -> 0.8
B7: L-04 | C7: Cedar City, UT | D7: Brentwood, CA | E7: Pipe | F7: Heavy | G7: 2326.74 | H7: 675 | I7: 249 | J7: =H7+I7 -> 924 | K7: =J7/Assumptions!$C$53 -> 17.769231 | L7: 2 | M7: =K7+L7 -> 19.769231 | N7: =IFERROR(G7/J7,0) -> 2.5181169 | O7: =IF(F7="Heavy",Assumptions!$C$9,IF(F7="Medium",Assumptions!$C$10,Assumptions!$C$11)) -> 7 | P7: =J7/O7*Assumptions!$C$8 -> 538.032 | Q7: =J7*Assumptions!$C$19 -> 221.76 | R7: =J7*Assumptions!$C$30 -> 102.84346 | S7: =P7+Q7+R7 -> 862.63546 | T7: =G7-S7 -> 1464.1045 | U7: =IFERROR(T7/J7,0) -> 1.5845287 | V7: =IFERROR(T7/M7,0) -> 74.059763 | W7: =IFERROR(I7/J7,0) -> 0.26948052 | X7: =IF(U7>=RATE5,5,IF(U7>=RATE4,4,IF(U7>=RATE3,3,IF(U7>=RATE2,2,1)))) -> 5 | Y7: 4 | Z7: =IF(V7>=TIME5,5,IF(V7>=TIME4,4,IF(V7>=TIME3,3,IF(V7>=TIME2,2,1)))) -> 5 | AA7: =IF(W7<=0.05,5,IF(W7<=0.1,4,IF(W7<=0.18,3,IF(W7<=0.28,2,1)))) -> 2 | AB7: 5 | AC7: 5 | AD7: 4 | AE7: 5 | AF7: =X7*WRATE+Y7*WDEST+Z7*WTIME+AA7*WDH+AB7*WDWELL+AC7*WSEC+AD7*WROUTE+AE7*WHOS -> 4.4 | AG7: =IF(OR(T7<0,W7>Assumptions!$C$49,AE7<=1),"FAIL","PASS") -> PASS | AH7: =IF(AG7="FAIL","DECLINE - gate",IF(AF7>=Assumptions!$C$50,"ACCEPT",IF(AF7>=Assumptions!$C$51,"NEGOTIATE","DECLINE - score"))) -> ACCEPT | AI7: 10 | AJ7: =AF7*2-AI7 -> -1.2
B8: L-05 | C8: Oakland, CA | D8: Mead, CO | E8: Wood products, tarped | F8: Heavy | G8: 2996.35 | H8: 1205 | I8: 46 | J8: =H8+I8 -> 1251 | K8: =J8/Assumptions!$C$53 -> 24.057692 | L8: 1.5 | M8: =K8+L8 -> 25.557692 | N8: =IFERROR(G8/J8,0) -> 2.3951639 | O8: =IF(F8="Heavy",Assumptions!$C$9,IF(F8="Medium",Assumptions!$C$10,Assumptions!$C$11)) -> 7 | P8: =J8/O8*Assumptions!$C$8 -> 728.43943 | Q8: =J8*Assumptions!$C$19 -> 300.24 | R8: =J8*Assumptions!$C$30 -> 139.23936 | S8: =P8+Q8+R8 -> 1167.9188 | T8: =G8-S8 -> 1828.4312 | U8: =IFERROR(T8/J8,0) -> 1.4615757 | V8: =IFERROR(T8/M8,0) -> 71.541326 | W8: =IFERROR(I8/J8,0) -> 0.036770584 | X8: =IF(U8>=RATE5,5,IF(U8>=RATE4,4,IF(U8>=RATE3,3,IF(U8>=RATE2,2,1)))) -> 4 | Y8: 4 | Z8: =IF(V8>=TIME5,5,IF(V8>=TIME4,4,IF(V8>=TIME3,3,IF(V8>=TIME2,2,1)))) -> 4 | AA8: =IF(W8<=0.05,5,IF(W8<=0.1,4,IF(W8<=0.18,3,IF(W8<=0.28,2,1)))) -> 5 | AB8: 4 | AC8: 3 | AD8: 3 | AE8: 5 | AF8: =X8*WRATE+Y8*WDEST+Z8*WTIME+AA8*WDH+AB8*WDWELL+AC8*WSEC+AD8*WROUTE+AE8*WHOS -> 4.05 | AG8: =IF(OR(T8<0,W8>Assumptions!$C$49,AE8<=1),"FAIL","PASS") -> PASS | AH8: =IF(AG8="FAIL","DECLINE - gate",IF(AF8>=Assumptions!$C$50,"ACCEPT",IF(AF8>=Assumptions!$C$51,"NEGOTIATE","DECLINE - score"))) -> ACCEPT | AI8: 9 | AJ8: =AF8*2-AI8 -> -0.9
B9: L-06 | C9: Pueblo, CO | D9: Stillwater, OK | E9: Steel rod / bar | F9: Heavy | G9: 963.84 | H9: 529 | I9: 150 | J9: =H9+I9 -> 679 | K9: =J9/Assumptions!$C$53 -> 13.057692 | L9: 1.5 | M9: =K9+L9 -> 14.557692 | N9: =IFERROR(G9/J9,0) -> 1.4194993 | O9: =IF(F9="Heavy",Assumptions!$C$9,IF(F9="Medium",Assumptions!$C$10,Assumptions!$C$11)) -> 7 | P9: =J9/O9*Assumptions!$C$8 -> 395.372 | Q9: =J9*Assumptions!$C$19 -> 162.96 | R9: =J9*Assumptions!$C$30 -> 75.574362 | S9: =P9+Q9+R9 -> 633.90636 | T9: =G9-S9 -> 329.93364 | U9: =IFERROR(T9/J9,0) -> 0.4859111 | V9: =IFERROR(T9/M9,0) -> 22.663869 | W9: =IFERROR(I9/J9,0) -> 0.22091311 | X9: =IF(U9>=RATE5,5,IF(U9>=RATE4,4,IF(U9>=RATE3,3,IF(U9>=RATE2,2,1)))) -> 1 | Y9: 3 | Z9: =IF(V9>=TIME5,5,IF(V9>=TIME4,4,IF(V9>=TIME3,3,IF(V9>=TIME2,2,1)))) -> 1 | AA9: =IF(W9<=0.05,5,IF(W9<=0.1,4,IF(W9<=0.18,3,IF(W9<=0.28,2,1)))) -> 2 | AB9: 4 | AC9: 4 | AD9: 4 | AE9: 5 | AF9: =X9*WRATE+Y9*WDEST+Z9*WTIME+AA9*WDH+AB9*WDWELL+AC9*WSEC+AD9*WROUTE+AE9*WHOS -> 2.4 | AG9: =IF(OR(T9<0,W9>Assumptions!$C$49,AE9<=1),"FAIL","PASS") -> PASS | AH9: =IF(AG9="FAIL","DECLINE - gate",IF(AF9>=Assumptions!$C$50,"ACCEPT",IF(AF9>=Assumptions!$C$51,"NEGOTIATE","DECLINE - score"))) -> DECLINE - score | AI9: 5 | AJ9: =AF9*2-AI9 -> -0.2
B10: L-07 | C10: Maize, KS | D10: Sikeston, MO | E10: Pipe, irregular | F10: Heavy | G10: 1297.33 | H10: 511 | I10: 135 | J10: =H10+I10 -> 646 | K10: =J10/Assumptions!$C$53 -> 12.423077 | L10: 2.5 | M10: =K10+L10 -> 14.923077 | N10: =IFERROR(G10/J10,0) -> 2.0082508 | O10: =IF(F10="Heavy",Assumptions!$C$9,IF(F10="Medium",Assumptions!$C$10,Assumptions!$C$11)) -> 7 | P10: =J10/O10*Assumptions!$C$8 -> 376.15657 | Q10: =J10*Assumptions!$C$19 -> 155.04 | R10: =J10*Assumptions!$C$30 -> 71.901381 | S10: =P10+Q10+R10 -> 603.09795 | T10: =G10-S10 -> 694.23205 | U10: =IFERROR(T10/J10,0) -> 1.0746626 | V10: =IFERROR(T10/M10,0) -> 46.520704 | W10: =IFERROR(I10/J10,0) -> 0.20897833 | X10: =IF(U10>=RATE5,5,IF(U10>=RATE4,4,IF(U10>=RATE3,3,IF(U10>=RATE2,2,1)))) -> 2 | Y10: 4 | Z10: =IF(V10>=TIME5,5,IF(V10>=TIME4,4,IF(V10>=TIME3,3,IF(V10>=TIME2,2,1)))) -> 1 | AA10: =IF(W10<=0.05,5,IF(W10<=0.1,4,IF(W10<=0.18,3,IF(W10<=0.28,2,1)))) -> 2 | AB10: 4 | AC10: 3 | AD10: 4 | AE10: 5 | AF10: =X10*WRATE+Y10*WDEST+Z10*WTIME+AA10*WDH+AB10*WDWELL+AC10*WSEC+AD10*WROUTE+AE10*WHOS -> 2.85 | AG10: =IF(OR(T10<0,W10>Assumptions!$C$49,AE10<=1),"FAIL","PASS") -> PASS | AH10: =IF(AG10="FAIL","DECLINE - gate",IF(AF10>=Assumptions!$C$50,"ACCEPT",IF(AF10>=Assumptions!$C$51,"NEGOTIATE","DECLINE - score"))) -> DECLINE - score | AI10: 9 | AJ10: =AF10*2-AI10 -> -3.3
B11: L-08 | C11: Troy, IL | D11: Sulphur, LA | E11: Strut / fittings, 2.5k lb | F11: Light | G11: 1802.44 | H11: 741 | I11: 165 | J11: =H11+I11 -> 906 | K11: =J11/Assumptions!$C$53 -> 17.423077 | L11: 0.5 | M11: =K11+L11 -> 17.923077 | N11: =IFERROR(G11/J11,0) -> 1.9894481 | O11: =IF(F11="Heavy",Assumptions!$C$9,IF(F11="Medium",Assumptions!$C$10,Assumptions!$C$11)) -> 10 | P11: =J11/O11*Assumptions!$C$8 -> 369.2856 | Q11: =J11*Assumptions!$C$19 -> 217.44 | R11: =J11*Assumptions!$C$30 -> 100.84002 | S11: =P11+Q11+R11 -> 687.56562 | T11: =G11-S11 -> 1114.8744 | U11: =IFERROR(T11/J11,0) -> 1.2305457 | V11: =IFERROR(T11/M11,0) -> 62.203292 | W11: =IFERROR(I11/J11,0) -> 0.18211921 | X11: =IF(U11>=RATE5,5,IF(U11>=RATE4,4,IF(U11>=RATE3,3,IF(U11>=RATE2,2,1)))) -> 3 | Y11: 4 | Z11: =IF(V11>=TIME5,5,IF(V11>=TIME4,4,IF(V11>=TIME3,3,IF(V11>=TIME2,2,1)))) -> 3 | AA11: =IF(W11<=0.05,5,IF(W11<=0.1,4,IF(W11<=0.18,3,IF(W11<=0.28,2,1)))) -> 2 | AB11: 5 | AC11: 5 | AD11: 4 | AE11: 5 | AF11: =X11*WRATE+Y11*WDEST+Z11*WTIME+AA11*WDH+AB11*WDWELL+AC11*WSEC+AD11*WROUTE+AE11*WHOS -> 3.6 | AG11: =IF(OR(T11<0,W11>Assumptions!$C$49,AE11<=1),"FAIL","PASS") -> PASS | AH11: =IF(AG11="FAIL","DECLINE - gate",IF(AF11>=Assumptions!$C$50,"ACCEPT",IF(AF11>=Assumptions!$C$51,"NEGOTIATE","DECLINE - score"))) -> NEGOTIATE | AI11: 10 | AJ11: =AF11*2-AI11 -> -2.8
B12: L-09 | C12: Joyce, LA | D12: Elmendorf, TX | E12: Lumber, tarped | F12: Heavy | G12: 1433.28 | H12: 439 | I12: 165 | J12: =H12+I12 -> 604 | K12: =J12/Assumptions!$C$53 -> 11.615385 | L12: 1.5 | M12: =K12+L12 -> 13.115385 | N12: =IFERROR(G12/J12,0) -> 2.3729801 | O12: =IF(F12="Heavy",Assumptions!$C$9,IF(F12="Medium",Assumptions!$C$10,Assumptions!$C$11)) -> 7 | P12: =J12/O12*Assumptions!$C$8 -> 351.70057 | Q12: =J12*Assumptions!$C$19 -> 144.96 | R12: =J12*Assumptions!$C$30 -> 67.226678 | S12: =P12+Q12+R12 -> 563.88725 | T12: =G12-S12 -> 869.39275 | U12: =IFERROR(T12/J12,0) -> 1.439392 | V12: =IFERROR(T12/M12,0) -> 66.28801 | W12: =IFERROR(I12/J12,0) -> 0.27317881 | X12: =IF(U12>=RATE5,5,IF(U12>=RATE4,4,IF(U12>=RATE3,3,IF(U12>=RATE2,2,1)))) -> 4 | Y12: 4 | Z12: =IF(V12>=TIME5,5,IF(V12>=TIME4,4,IF(V12>=TIME3,3,IF(V12>=TIME2,2,1)))) -> 3 | AA12: =IF(W12<=0.05,5,IF(W12<=0.1,4,IF(W12<=0.18,3,IF(W12<=0.28,2,1)))) -> 2 | AB12: 5 | AC12: 4 | AD12: 4 | AE12: 5 | AF12: =X12*WRATE+Y12*WDEST+Z12*WTIME+AA12*WDH+AB12*WDWELL+AC12*WSEC+AD12*WROUTE+AE12*WHOS -> 3.8 | AG12: =IF(OR(T12<0,W12>Assumptions!$C$49,AE12<=1),"FAIL","PASS") -> PASS | AH12: =IF(AG12="FAIL","DECLINE - gate",IF(AF12>=Assumptions!$C$50,"ACCEPT",IF(AF12>=Assumptions!$C$51,"NEGOTIATE","DECLINE - score"))) -> ACCEPT | AI12: 8 | AJ12: =AF12*2-AI12 -> -0.4
B13: L-10 | C13: Houston, TX | D13: Ontario, CA | E13: Metal building | F13: Heavy | G13: 3404.23 | H13: 1476 | I13: 201 | J13: =H13+I13 -> 1677 | K13: =J13/Assumptions!$C$53 -> 32.25 | L13: 2 | M13: =K13+L13 -> 34.25 | N13: =IFERROR(G13/J13,0) -> 2.0299523 | O13: =IF(F13="Heavy",Assumptions!$C$9,IF(F13="Medium",Assumptions!$C$10,Assumptions!$C$11)) -> 7 | P13: =J13/O13*Assumptions!$C$8 -> 976.49314 | Q13: =J13*Assumptions!$C$19 -> 402.48 | R13: =J13*Assumptions!$C$30 -> 186.6542 | S13: =P13+Q13+R13 -> 1565.6273 | T13: =G13-S13 -> 1838.6027 | U13: =IFERROR(T13/J13,0) -> 1.0963641 | V13: =IFERROR(T13/M13,0) -> 53.681829 | W13: =IFERROR(I13/J13,0) -> 0.11985689 | X13: =IF(U13>=RATE5,5,IF(U13>=RATE4,4,IF(U13>=RATE3,3,IF(U13>=RATE2,2,1)))) -> 2 | Y13: 3 | Z13: =IF(V13>=TIME5,5,IF(V13>=TIME4,4,IF(V13>=TIME3,3,IF(V13>=TIME2,2,1)))) -> 2 | AA13: =IF(W13<=0.05,5,IF(W13<=0.1,4,IF(W13<=0.18,3,IF(W13<=0.28,2,1)))) -> 3 | AB13: 3 | AC13: 4 | AD13: 3 | AE13: 5 | AF13: =X13*WRATE+Y13*WDEST+Z13*WTIME+AA13*WDH+AB13*WDWELL+AC13*WSEC+AD13*WROUTE+AE13*WHOS -> 2.75 | AG13: =IF(OR(T13<0,W13>Assumptions!$C$49,AE13<=1),"FAIL","PASS") -> PASS | AH13: =IF(AG13="FAIL","DECLINE - gate",IF(AF13>=Assumptions!$C$50,"ACCEPT",IF(AF13>=Assumptions!$C$51,"NEGOTIATE","DECLINE - score"))) -> DECLINE - score | AI13: 7 | AJ13: =AF13*2-AI13 -> -1.5
B14: L-11 | C14: Visalia, CA | D14: Roseburg, OR | E14: Metal building, 11k lb | F14: Light | G14: 1496.27 | H14: 612 | I14: 218 | J14: =H14+I14 -> 830 | K14: =J14/Assumptions!$C$53 -> 15.961538 | L14: 1.5 | M14: =K14+L14 -> 17.461538 | N14: =IFERROR(G14/J14,0) -> 1.8027349 | O14: =IF(F14="Heavy",Assumptions!$C$9,IF(F14="Medium",Assumptions!$C$10,Assumptions!$C$11)) -> 10 | P14: =J14/O14*Assumptions!$C$8 -> 338.308 | Q14: =J14*Assumptions!$C$19 -> 199.2 | R14: =J14*Assumptions!$C$30 -> 92.381031 | S14: =P14+Q14+R14 -> 629.88903 | T14: =G14-S14 -> 866.38097 | U14: =IFERROR(T14/J14,0) -> 1.0438325 | V14: =IFERROR(T14/M14,0) -> 49.616531 | W14: =IFERROR(I14/J14,0) -> 0.2626506 | X14: =IF(U14>=RATE5,5,IF(U14>=RATE4,4,IF(U14>=RATE3,3,IF(U14>=RATE2,2,1)))) -> 1 | Y14: 3 | Z14: =IF(V14>=TIME5,5,IF(V14>=TIME4,4,IF(V14>=TIME3,3,IF(V14>=TIME2,2,1)))) -> 1 | AA14: =IF(W14<=0.05,5,IF(W14<=0.1,4,IF(W14<=0.18,3,IF(W14<=0.28,2,1)))) -> 2 | AB14: 4 | AC14: 4 | AD14: 3 | AE14: 5 | AF14: =X14*WRATE+Y14*WDEST+Z14*WTIME+AA14*WDH+AB14*WDWELL+AC14*WSEC+AD14*WROUTE+AE14*WHOS -> 2.35 | AG14: =IF(OR(T14<0,W14>Assumptions!$C$49,AE14<=1),"FAIL","PASS") -> PASS | AH14: =IF(AG14="FAIL","DECLINE - gate",IF(AF14>=Assumptions!$C$50,"ACCEPT",IF(AF14>=Assumptions!$C$51,"NEGOTIATE","DECLINE - score"))) -> DECLINE - score | AI14: 8 | AJ14: =AF14*2-AI14 -> -3.3
B15: L-12 | C15: Riddle, OR | D15: Midlothian, TX | E15: Lumber | F15: Heavy | G15: 4124.08 | H15: 2044 | I15: 23 | J15: =H15+I15 -> 2067 | K15: =J15/Assumptions!$C$53 -> 39.75 | L15: 2 | M15: =K15+L15 -> 41.75 | N15: =IFERROR(G15/J15,0) -> 1.9952008 | O15: =IF(F15="Heavy",Assumptions!$C$9,IF(F15="Medium",Assumptions!$C$10,Assumptions!$C$11)) -> 7 | P15: =J15/O15*Assumptions!$C$8 -> 1203.5846 | Q15: =J15*Assumptions!$C$19 -> 496.08 | R15: =J15*Assumptions!$C$30 -> 230.06216 | S15: =P15+Q15+R15 -> 1929.7267 | T15: =G15-S15 -> 2194.3533 | U15: =IFERROR(T15/J15,0) -> 1.0616126 | V15: =IFERROR(T15/M15,0) -> 52.55936 | W15: =IFERROR(I15/J15,0) -> 0.011127238 | X15: =IF(U15>=RATE5,5,IF(U15>=RATE4,4,IF(U15>=RATE3,3,IF(U15>=RATE2,2,1)))) -> 2 | Y15: 4 | Z15: =IF(V15>=TIME5,5,IF(V15>=TIME4,4,IF(V15>=TIME3,3,IF(V15>=TIME2,2,1)))) -> 2 | AA15: =IF(W15<=0.05,5,IF(W15<=0.1,4,IF(W15<=0.18,3,IF(W15<=0.28,2,1)))) -> 5 | AB15: 4 | AC15: 4 | AD15: 1 | AE15: 4 | AF15: =X15*WRATE+Y15*WDEST+Z15*WTIME+AA15*WDH+AB15*WDWELL+AC15*WSEC+AD15*WROUTE+AE15*WHOS -> 3.15 | AG15: =IF(OR(T15<0,W15>Assumptions!$C$49,AE15<=1),"FAIL","PASS") -> PASS | AH15: =IF(AG15="FAIL","DECLINE - gate",IF(AF15>=Assumptions!$C$50,"ACCEPT",IF(AF15>=Assumptions!$C$51,"NEGOTIATE","DECLINE - score"))) -> NEGOTIATE | AI15: 5 | AJ15: =AF15*2-AI15 -> 1.3
... B21: L-18 | C21: Blytheville, AR | D21: W Palm Beach, FL (HOME) | E21: Roofing, repower | F21: Heavy | G21: 2951.03 | H21: 894 | I21: 265 | J21: =H21+I21 -> 1159 | K21: =J21/Assumptions!$C$53 -> 22.288462 | L21: 3 | M21: =K21+L21 -> 25.288462 | N21: =IFERROR(G21/J21,0) -> 2.5461864 | O21: =IF(F21="Heavy",Assumptions!$C$9,IF(F21="Medium",Assumptions!$C$10,Assumptions!$C$11)) -> 7 | P21: =J21/O21*Assumptions!$C$8 -> 674.86914 | Q21: =J21*Assumptions!$C$19 -> 278.16 | R21: =J21*Assumptions!$C$30 -> 128.99954 | S21: =P21+Q21+R21 -> 1082.0287 | T21: =G21-S21 -> 1869.0013 | U21: =IFERROR(T21/J21,0) -> 1.6125982 | V21: =IFERROR(T21/M21,0) -> 73.907277 | W21: =IFERROR(I21/J21,0) -> 0.22864538 | X21: =IF(U21>=RATE5,5,IF(U21>=RATE4,4,IF(U21>=RATE3,3,IF(U21>=RATE2,2,1)))) -> 5 | Y21: 5 | Z21: =IF(V21>=TIME5,5,IF(V21>=TIME4,4,IF(V21>=TIME3,3,IF(V21>=TIME2,2,1)))) -> 4 | AA21: =IF(W21<=0.05,5,IF(W21<=0.1,4,IF(W21<=0.18,3,IF(W21<=0.28,2,1)))) -> 2 | AB21: 3 | AC21: 3 | AD21: 3 | AE21: 3 | AF21: =X21*WRATE+Y21*WDEST+Z21*WTIME+AA21*WDH+AB21*WDWELL+AC21*WSEC+AD21*WROUTE+AE21*WHOS -> 4.05 | AG21: =IF(OR(T21<0,W21>Assumptions!$C$49,AE21<=1),"FAIL","PASS") -> PASS | AH21: =IF(AG21="FAIL","DECLINE - gate",IF(AF21>=Assumptions!$C$50,"ACCEPT",IF(AF21>=Assumptions!$C$51,"NEGOTIATE","DECLINE - score"))) -> ACCEPT | AI21: 9 | AJ21: =AF21*2-AI21 -> -0.9
B23: TOTALS | G23: =SUM(G4:G21) -> 41501.02 | H23: =SUM(H4:H21) -> 16783 | I23: =SUM(I4:I21) -> 2431 | J23: =SUM(J4:J21) -> 19214 | M23: =SUM(M4:M21) -> 401 | N23: =G23/J23 -> 2.1599365 | P23: =SUM(P4:P21) -> 10246.924 | S23: =SUM(S4:S21) -> 16996.849 | T23: =SUM(T4:T21) -> 24504.171 | U23: =T23/J23 -> 1.275329 | W23: =I23/J23 -> 0.12652233 | AF23: =AVERAGE(AF4:AF21) -> 3.5638889 | AI23: =AVERAGE(AI4:AI21) -> 8.5
B25: Var = model score doubled to a 10-point scale, minus operator score. Positive means the model rated the load higher than the operator did.
B26: Weight class drives MPG, which drives fuel cost, which drives net contribution. Changing a class re-prices the load end to end.

Sheet Scoring Rules
B2: SCORING RULES & WEIGHTS
B3: Weights must total 100%. Rate and time bands were re-cut in v3 because the source-checked cost stack moved the break-even floor.
B5: Dimension | C5: Weight | D5: Type | E5: Score 5 | F5: Score 4 | G5: Score 3 | H5: Score 2 | I5: Score 1
B6: Rate quality (net $ per total mile) | C6: 0.25 | D6: Calculated | E6: see bands below | F6: see bands below | G6: see bands below | H6: see bands below | I6: see bands below
B7: Destination value (reload / hub / home) | C7: 0.25 | D7: Judgment | E7: Hub or home | F7: Strong market | G7: Average | H7: Weak | I7: Dead market
B8: Time efficiency (net $ per hour) | C8: 0.15 | D8: Calculated | E8: see bands below | F8: see bands below | G8: see bands below | H8: see bands below | I8: see bands below
B9: Deadhead efficiency (% empty) | C9: 0.1 | D9: Calculated | E9: <= 5% | F9: <= 10% | G9: <= 18% | H9: <= 28% | I9: > 28%
B10: Dwell / detention risk | C10: 0.1 | D10: Judgment | E10: Drop & hook | F10: Live, on time | G10: Mixed history | H10: Slow facility | I10: Known problem
B11: Securement / handling burden | C11: 0.05 | D11: Judgment | E11: No tarp | F11: Light tarp | G11: Full tarp | H11: Tarp + permit | I11: Oversize + escort
B12: Route conditions | C12: 0.05 | D12: Judgment | E12: Flat, cheap fuel | F12: Minor grades | G12: Mixed | H12: Heavy grades | I12: No parking / severe
B13: HOS & appointment feasibility | C13: 0.05 | D13: Judgment | E13: Ample margin | F13: Comfortable | G13: Tight but legal | H13: Very tight | I13: Not legal
B14: TOTAL WEIGHT | C14: =SUM(C6:C13) -> 1 | E14: =IF(ABS(C14-1)<0.0001,"Balanced","ERROR - must total 100%") -> Balanced
B16: CALCULATED BANDS (edit these numbers to re-cut the scale)
B17: Dimension | C17: Score 5 | D17: Score 4 | E17: Score 3 | F17: Score 2 | G17: below = 1
B18: Rate — net $ per total mile | C18: 1.58 | D18: 1.43 | E18: 1.23 | F18: 1.06 | G18: anything lower
B19: Time — net $ per hour committed | C19: 74 | D19: 68 | E19: 57 | F19: 50 | G19: anything lower
B21: WHY THESE WEIGHTS AND BANDS
B22: Rate and destination carry 25% each. Correlation between operator score and net rate per mile across the 18 loads is 0.62, so rate explains
B23: under 40% of accept decisions. The residuals cluster on loads routing toward a terminal or toward home, which is what forced destination up
B24: from the 15% it carried in v1.
B26: Securement sits at 5%. Tarp pay of $90 to $150 arrives as a revenue line on the rate confirmation — the operating statement shows $2,620
B27: of tarp pay year to date — so the labour is already compensated in the numerator. Weighting it again double-counts it.
B29: The rate band has been re-cut at every change to the cost floor. v1 used $0.60 for a 5 against a $1.342 floor. Removing the phantom truck
B30: payment moved it to $1.50, and adding a tire reserve the statement does not carry moved it to $1.58. A band that does not move when the
B31: floor moves stops discriminating: at the v1 setting, seventeen of eighteen loads score a 5.

Sheet Settlement Recon
B2: SETTLEMENT RECONCILIATION
B3: Source: Prime Inc. settlement and operating statement, week ending 26/07/31, 237 weeks in service. Not published with this workbook — it carries bank and customer detail.
B5: THE RECONCILED TRIP — the one load in the sample that can be checked against a settlement
B6: This is L-18. Blytheville AR to a Jacksonville FL stop-off to West Palm Beach FL, repowered.
B7: Line | C7: App estimate | D7: Settlement | E7: Delta | F7: Note
B8: Loaded miles | C8: 894 | D8: 894 | E8: exact | F8: Matches to the mile.
B9: Empty miles | C9: 265 | D9: 204 | E9: -61 | F9: App showed more. Cause unconfirmed — repower segment or a different mileage basis.
B10: Total miles | C10: 1159 | D10: 1098 | E10: -61 | F10: 5.3% fewer paid miles on this trip. One observation, not a pattern.
B11: Linehaul (owner share) | C11: 2367.83 | D11: 2367.94 | E11: +0.11 | F11: 72% owner split of $3,288.81 trip revenue. Rounding only.
B12: Fuel surcharge | C12: 439.2 | D12: 439.2 | E12: 0.00 | F12: Exact.
B13: Stop / pickup pay | C13: 144 | D13: 144 | E13: 0.00 | F13: Exact.
B14: Longevity pay | C14: 0 | D14: 21.96 | E14: +21.96 | F14: Does not appear in the app.
B15: Toll reimbursement | C15: 0 | D15: 13.33 | E15: +13.33 | F15: Does not appear in the app.
B16: TOTAL REVENUE | C16: 2951.03 | D16: 2986.43 | E16: +35.40 | F16: App understates revenue by the two lines above.
B17: Rate per total mile | C17: 2.546 | D17: 2.72 | E17: +0.174 | F17: On this trip, both differences push the settled rate above the app estimate.
B19: The customer was billed $4,490.41 on this load (1,049 miles at $3.50 plus $618.91 fuel surcharge and a $200 stop charge).
B20: The operator received $2,986.43 of that, or 66.5%, because the 72% split applies only to the trip revenue portion actually run.
B22: IS THE 18-LOAD SAMPLE REPRESENTATIVE?
B23: Measure | C23: 18-load sample | D23: Statement YTD | E23: Statement LTD | F23: Note
B24: Total revenue per mile | C24: ='Load Board'!N23 -> 2.1599365 | D24: 2.163 | E24: 2.125 | F24: Sample and YTD agree to 0.15%. The 18 loads are a fair slice of the year.
B25: Net per mile after all-in cost | C25: ='Load Board'!U23 -> 1.275329 | D25: 1.24 | E25: 0.783 | F25: Sample runs higher: five of the eighteen loads are light freight at 10 mpg, so its blended fuel cost is below the YTD average.
B26: Miles | C26: ='Load Board'!J23 -> 19214 | D26: 56752 | E26: 460589 | F26: Sample is 34% of the year to date and 4.2% of lifetime miles.
B27: Deadhead | C27: ='Load Board'!W23 -> 0.12652233 | D27: — | E27: — | F27: No statement equivalent; Prime reports paid empty miles per trip only.
B29: COST STACK — WHAT v2 ESTIMATED VS WHAT THE STATEMENT SHOWS
B30: Cost line | C30: v2 estimate | D30: Statement YTD | E30: v3 setting | F30: Basis for the v3 number
B31: Diesel, pump | C31: $3.700/gal | D31: $4.933/gal | E31: $4.933/gal | F31: Settlement week: 120.3 gallons for $593.44.
B32: Fuel discount | C32: not modelled | D32: $0.857/gal | E32: $0.857/gal | F32: YTD $0.119/mi at 7.20 blended mpg.
B33: Maintenance & repair | C33: $0.180 | D33: $0.065 | E33: $0.120 | F33: Split between the actual and the prior reserve. See note below.
B34: Tires | C34: $0.045 | D34: $0.000 (absent) | E34: $0.045 | F34: Statement shows zero because no tire fund exists for owner-operators. Cost is real and paid personally.
B35: Tolls, Qualcomm, misc | C35: $0.035 | D35: $0.045 | E35: $0.045 | F35: Statement miscellaneous, less advances and emergency-fund transfers.
B36: Total fixed | C36: $0.190 | D36: $0.128 | E36: $0.111 | F36: Rebuilt from seven statement lines, divided by 114,400 rather than the statement's own mileage.
B37: Annual miles | C37: 120,000 | D37: 101,057 lifetime | E37: 114,400 | F37: Statement average includes a 7-month home-time year. Rebuilt as 44 working weeks x 2,600 mi.
B38: ALL-IN, heavy load | C38: $0.999 | D38: — | E38: $0.934 | F38: Ties to the statement within $0.006 on a like-for-like basis. See the reconciliation below.
B40: WHAT THIS STATEMENT DOES NOT COVER
B41: Every lifetime figure in this workbook is labelled LTD, and that label is misleading unless it is qualified. It means life of the current
B42: tractor, not life of the operator at this carrier.
B44: Tenure at Prime Inc. March 2018 to present, roughly 8.4 years.
B45: Covered by these figures January 2022 to present, 237 weeks, one tractor.
B46: Not covered July 2018 to December 2021, the previous tractor, roughly 3.5 years of own-truck operation.
B47: Also not the operator's miles March to July 2018, in a trainer's truck for the 50,000 miles required to earn an A-seat.
...

Sheet Score a Load
B2: SCORE A LOAD BEFORE YOU ACCEPT IT
B3: Fill the yellow cells. Answer the two gate questions first — if either fails, the score is irrelevant.
B5: HARD GATES
B6: Can you legally make the delivery window? | C6: YES | D6: YES or NO. Check the clock before anything else.
B7: Is the shipper or receiver blacklisted? | C7: NO | D7: NO or YES. Three facilities sit on this list.
B8: Gate result | C8: =IF(AND(UPPER(C6)="YES",UPPER(C7)="NO"),"PASS","STOP - DECLINE") -> PASS
B10: LOAD DETAILS
B11: Total miles (loaded + empty) | C11: 1098 | D11: Add both. Use settled miles if you have them; the app runs about 5% high.
B12: Of that, empty miles | C12: 204 | D12: Drives gate 2 and the deadhead dimension.
B13: Estimated revenue ($) | C13: 2986.43 | D13: All in — linehaul, fuel surcharge, tarp, stop pay, longevity, tolls.
B14: Weight class | C14: Heavy | D14: Heavy, Medium or Light. Infer from commodity: foam, panel, AC unit, strut run light. Pipe, coil, rod, bar, lumber run heavy.
B15: Estimated total hours (drive + dwell) | C15: 24 | D15: Drive time at roughly 52 mph plus expected loading, securement and dwell.
B17: JUDGMENT SCORES (1 to 5 — see Scoring Rules)
B18: Destination value | C18: 5 | D18: 5 = hub (Springfield, Pittston, Salt Lake, Minooka, Laredo) or routing home. 3 = average. 1 = dead end.
B19: Dwell / detention risk | C19: 3 | D19: 5 = drop and hook or a facility you know how to work. 1 = a known problem receiver.
B20: Securement / handling burden | C20: 3 | D20: 5 = no tarp. 1 = oversize with escort. Tarp pay already compensates this in revenue.
B21: Route conditions | C21: 3 | D21: 5 = flat with cheap fuel and good parking. 1 = heavy grades, no signal, nowhere to shut down.
B22: HOS & appointment feasibility | C22: 3 | D22: 5 = ample margin. 1 = not legally possible, which also trips gate 3.
B24: RESULT
B25: Gross rate per total mile | C25: =IFERROR(C13/C11,0) -> 2.7198816
B26: Estimated MPG | C26: =IF(C14="Heavy",Assumptions!$C$9,IF(C14="Medium",Assumptions!$C$10,Assumptions!$C$11)) -> 7 | D26: From the weight-class band on Assumptions.
B27: Fuel cost | C27: =IFERROR(C11/C26*Assumptions!$C$8,0) -> 639.34971 | D27: Net of the Prime discount.
B28: Other variable cost | C28: =C11*Assumptions!$C$19 -> 263.52
B29: Fixed cost | C29: =C11*Assumptions!$C$30 -> 122.21009
B30: Total cost | C30: =C27+C28+C29 -> 1025.0798
B31: Net contribution | C31: =C13-C30 -> 1961.3502 | D31: What the load leaves behind after every mile is paid for.
B32: Net $ per total mile | C32: =IFERROR(C31/C11,0) -> 1.7862934
B33: Net $ per hour committed | C33: =IFERROR(C31/C15,0) -> 81.722925 | D33: A well-paying load that burns eleven hours at a slow facility is a poor use of a finite clock.
B34: Deadhead % | C34: =IFERROR(C12/C11,0) -> 0.18579235 | D34: Above the tolerance on Assumptions this trips gate 2 regardless of score.
B36: WEIGHTED SCORE (1 to 5) | C36: =IF(C32>=RATE5,5,IF(C32>=RATE4,4,IF(C32>=RATE3,3,IF(C32>=RATE2,2,1))))*WRATE+C18*WDEST+IF(C33>=TIME5,5,IF(C33>=TIME4,4,IF(C33>=TIME3,3,IF(C33>=TIME2,2,1))))*WTIME+IF(C34<=0.05,5,IF(C34<=0.1,4,IF(C34<=0.18,3,IF(C34<=0.28,2,1))))*WDH+C19*WDWELL+C20*WSEC+C21*WROUTE+C22*WHOS -> 4.2 | D36: Same eight-dimension formula the Load Board uses.
B37: DECISION | C37: =IF(C8<>"PASS","DECLINE - gate 3",IF(C31<0,"DECLINE - gate 1",IF(C34>Assumptions!$C$49,"DECLINE - gate 2",IF(C36>=Assumptions!$C$50,"ACCEPT",IF(C36>=Assumptions!$C$51,"NEGOTIATE","DECLINE - score"))))) -> ACCEPT
B39: The example filled in is the reconciled trip (L-18) at its settled figures — 1,098 paid miles and $2,986.43, not the app estimate.
B41: DOCUMENTED EXCEPTION — RELATIONSHIP CAPITAL
B42: L-07 (Maize KS to Sikeston MO) was refused by three drivers before it was offered a fourth time and accepted. It scores below threshold on
B43: securement burden and rate. Accepting it was still correct: dispatch discretion over future load quality is worth more than the margin lost on
B44: one trip.
B46: A weighted average cannot price that. It is handled as a stated exception — below-threshold loads may be accepted where they buy dispatch
B47: goodwill, and each instance is logged so the pattern stays visible and the exception does not quietly become the rule.

Sheet Testing
B2: TESTING AGAINST RETROSPECTIVE RATINGS
B3: What this is and is not: the 18 loads were all accepted, and the operator scored them after delivery. This compares model output to retrospective quality ratings. It is not a test against accept-or-decline decisions.
B5: SAMPLE
B6: Loads | C6: =COUNT('Load Board'!G4:G21) -> 18
B7: Total revenue | C7: ='Load Board'!G23 -> 41501.02 | D7: Prime app trip history.
B8: Total miles | C8: ='Load Board'!J23 -> 19214
B9: Blended gross $/mile | C9: ='Load Board'!N23 -> 2.1599365 | D9: Statement YTD reads $2.163. See Settlement Recon.
B10: Blended net $/mile after all-in cost | C10: ='Load Board'!U23 -> 1.275329 | D10: Statement YTD net is $1.240. Sample runs higher: five of eighteen loads are light freight at 10 mpg.
B11: Deadhead | C11: ='Load Board'!W23 -> 0.12652233 | D11: Empty miles as a share of total.
B13: DOES THE MODEL AGREE WITH THE OPERATOR RATINGS?
B14: Correlation — operator score vs. gross $/mile | C14: =CORREL('Load Board'!AI4:AI21,'Load Board'!N4:N21) -> 0.5671398 | D14: Rate alone, before costing the load.
B15: Correlation — operator score vs. net $/mile | C15: =CORREL('Load Board'!AI4:AI21,'Load Board'!U4:U21) -> 0.61795732 | D15: Costing it properly improves the fit.
B16: Correlation — operator score vs. model score | C16: =CORREL('Load Board'!AI4:AI21,'Load Board'!AF4:AF21) -> 0.55609729 | D16: The full weighted model against post-delivery ratings.
B17: Variance explained | C17: =C16^2 -> 0.30924419 | D17: Share of the variance in the ratings, not in any decision.
B19: Mean operator score (1-10 scale) | C19: ='Load Board'!AI23 -> 8.5
B20: Mean model score, rescaled to 10 | C20: ='Load Board'!AF23*2 -> 7.1277778
B21: Level gap | C21: =C20-C19 -> -1.3722222 | D21: The operator rates leniently: 8.5 average on a scale where 10 means everything lined up.
B23: WHERE MODEL AND RATINGS LINE UP
B24: Lowest four by operator rating | C24: L-06, L-12, L-10, L-01
B25: Lowest four by model score | C25: L-11, L-06, L-10, L-07
B26: Highest four by operator rating | C26: L-04, L-08, L-13, L-14
B27: Highest four by model score | C27: L-13, L-16, L-03, L-04
B29: Two of the lowest four overlap and two of the highest four overlap. L-06 is the only load both place at the bottom, and it is the clearest
B30: case in the sample: $1.42 gross per mile against a linehaul near $0.95, with fuel surcharge carrying a third of the revenue.
B32: The disagreements teach more than the overlaps. L-14 and L-08 both rated 10 and both sit in the model's bottom half. L-14 routed home to
B33: Apollo Beach. L-08 was 2,500 lb of strut that ran 11 mpg and cleared the receiver in under thirty minutes. L-07 the model scores below the
B34: decline threshold; it was refused by three other drivers before being accepted deliberately to bank dispatch goodwill.
B36: Net dollars per mile taken alone correlates at 0.62, better than the full eight-dimension model at 0.56. Adding the judgment dimensions, at
B37: these weights, moved agreement with the ratings slightly in the wrong direction. That is reported rather than tuned away: with eighteen
B38: observations, adjusting weights until the correlation improves is fitting noise.
B40: What this exercise does not show is whether the model would have caught a load worth refusing. Every load in the sample was accepted, so
B41: the decline side has never been exercised. No claim is made about it.
B43: THREATS TO VALIDITY
B44: No decline data at all. All 18 loads were accepted. The model has never been scored against an offer that was refused, so nothing here speaks
... B61: Small n. Eighteen loads, one equipment type, one carrier, one operator. The weights are reasoned, not fitted.
